<?xml version="1.0" encoding="UTF-8"?>

<robot name="sam_bot">

  <!-- Robot Base -->
  <link name="base_link">
    <visual>
      <origin
        xyz="-0.30 -0.29 -0.2"
        rpy="0 0 0" />
      <geometry>
        <!-- <box size="${base_length} ${0.31} ${base_height}"/> -->
        <mesh filename="package://amr_description/meshes/DGT-001M.STL"/>
      </geometry>
      <material name="Cyan">
        <color rgba="0 1.0 1.0 1.0"/>
      </material>
    </visual>
    <collision>
      <origin
        xyz="-0.30 -0.29 -0.2"
        rpy="0 0 0" />
      <geometry>
        <mesh filename="package://amr_description/meshes/DGT-001M.STL"/>
      </geometry>
    </collision>
    <inertial>
         <origin
        xyz="-0.30 -0.29 -0.2"
        rpy="0 0 0" />
         <mass value="45.88" />
         <inertia ixx="1.182744" ixy="0.017957" ixz="-0.077476" iyx="0.017957" iyy="0.538664" iyz="0.000018" izx="-0.077476" izy="0.000018" izz="1.240229"/>
    </inertial>

    <!-- <xacro:box_inertia m="15" w="${0.31}" d="${base_length}" h="${base_height}"/> -->
  </link>
  <!-- Robot Footprint -->
  <link name="base_footprint"/>

  <joint name="base_joint" type="fixed">
    <parent link="base_footprint"/>
    <child link="base_link"/>
    <origin xyz="0.0 0.0 0.2" rpy="0 0 0"/>
  </joint>

  <!-- Wheels -->
    <link name="wheel_l_b_link">
      <visual>
        <origin xyz="0 0 0" rpy="1.57057 0 0"/>
        <geometry>
            <cylinder radius="0.15" length="0.08"/>
        </geometry>
        <material name="Gray">
          <color rgba="0.5 0.5 0.5 1.0"/>
        </material>
      </visual>
      <collision>
        <origin xyz="0 0 0" rpy="1.57057 0 0"/>
        <geometry>
          <cylinder radius="0.15" length="0.08"/>
        </geometry>
      </collision>
      <inertial>
         <origin rpy="0 0 0" xyz="0 0.05 0" />
         <mass value="4.195729" />
         <inertia ixx="0.063680" ixy="0.000000" ixz="0.000000" iyx="0.000000" iyy="0.121410" iyz="0.000000" izx="0.000000" izy="0.000000" izz="0.063680"/>
      </inertial>
    </link>
    <link name="wheel_r_b_link">
      <visual>
        <origin xyz="0 0 0" rpy="1.57057 0 0"/>
        <geometry>
            <cylinder radius="0.15" length="0.08"/>
        </geometry>
        <material name="Gray">
          <color rgba="0.5 0.5 0.5 1.0"/>
        </material>
      </visual>
            <collision>
        <origin xyz="0 0 0" rpy="1.57057 0 0"/>
        <geometry>
          <cylinder radius="0.15" length="0.08"/>
        </geometry>
      </collision>
      <inertial>
         <origin rpy="0 0 0" xyz="0 -0.05 0" />
         <mass value="4.195729" />
         <inertia ixx="0.063680" ixy="0.000000" ixz="0.000000" iyx="0.000000" iyy="0.121410" iyz="0.000000" izx="0.000000" izy="0.000000" izz="0.063680"/>
      </inertial>
    </link>
    <link name="wheel_l_f_link">
      <visual>
        <origin xyz="0 0 0" rpy="1.57057 0 0"/>
        <geometry>
            <cylinder radius="0.15" length="0.08"/>
        </geometry>
        <material name="Gray">
          <color rgba="0.5 0.5 0.5 1.0"/>
        </material>
      </visual>
            <collision>
        <origin xyz="0 0 0" rpy="1.57057 0 0"/>
        <geometry>
          <cylinder radius="0.15" length="0.08"/>
        </geometry>
      </collision>
      <inertial>
         <origin rpy="0 0 0" xyz="0 0.05 0" />
         <mass value="4.195729" />
         <inertia ixx="0.063680" ixy="0.000000" ixz="0.000000" iyx="0.000000" iyy="0.121410" iyz="0.000000" izx="0.000000" izy="0.000000" izz="0.063680"/>
      </inertial>
    </link>
    <link name="wheel_r_f_link">
      <visual>
        <origin xyz="0 0 0" rpy="1.57057 0 0"/>
        <geometry>
            <cylinder radius="0.15" length="0.08"/>
        </geometry>
        <material name="Gray">
          <color rgba="0.5 0.5 0.5 1.0"/>
        </material>
      </visual>
            <collision>
        <origin xyz="0 0 0" rpy="1.57057 0 0"/>
        <geometry>
          <cylinder radius="0.15" length="0.08"/>
        </geometry>
      </collision>
      <inertial>
         <origin rpy="0 0 0" xyz="0 -0.05 0" />
         <mass value="4.195729" />
         <inertia ixx="0.063680" ixy="0.000000" ixz="0.000000" iyx="0.000000" iyy="0.121410" iyz="0.000000" izx="0.000000" izy="0.000000" izz="0.063680"/>
      </inertial>
    </link>
    
    <joint name="wheel_l_b_joint" type="continuous">
      <parent link="base_link"/>
      <child link="wheel_l_b_link"/>
      <origin xyz="-0.15 0.245 -0.05" rpy="0 0 0"/>
      <axis xyz="0 1 0"/>
    </joint>
    <joint name="wheel_l_f_joint" type="continuous">
      <parent link="base_link"/>
      <child link="wheel_l_f_link"/>
      <origin xyz="0.23 0.245 -0.05" rpy="0 0 0"/>
      <axis xyz="0 1 0"/>
    </joint>
    <joint name="wheel_r_b_joint" type="continuous">
      <parent link="base_link"/>
      <child link="wheel_r_b_link"/>
      <origin xyz="-0.15 -0.245 -0.05" rpy="0 0 0"/>
      <axis xyz="0 1 0"/>
    </joint>
    <joint name="wheel_r_f_joint" type="continuous">
      <parent link="base_link"/>
      <child link="wheel_r_f_link"/>
      <origin xyz="0.23 -0.245 -0.05" rpy="0 0 0"/>
      <axis xyz="0 1 0"/>
    </joint>


  <link name="base_scan">
    <inertial>
        <origin xyz="0 0 0" rpy="0 0 0"/>
        <mass value="0.125"/>
        <inertia ixx="0.001"  ixy="0"  ixz="0" iyy="0.001" iyz="0" izz="0.001" />
    </inertial>

    <collision>
        <origin xyz="0 0 0" rpy="0 0 0"/>
        <geometry>
        <cylinder radius="0.0508" length="0.055"/>
        </geometry>
    </collision>

    <visual>
        <origin xyz="0 0 0" rpy="0 0 0"/>
        <geometry>
        <cylinder radius="0.0508" length="0.055"/>
        </geometry>
    </visual>
  </link>

<joint name="scan_joint" type="fixed">
  <parent link="base_link"/>
  <child link="base_scan"/>
  <origin xyz="0.25 0 0.45" rpy="0 0 0"/>
</joint>
<link name="camera_link">
  <visual>
    <origin xyz="0 0 0" rpy="0 0 0"/>
    <geometry>
      <box size="0.015 0.130 0.022"/>
    </geometry>
  </visual>

  <collision>
    <origin xyz="0 0 0" rpy="0 0 0"/>
    <geometry>
      <box size="0.015 0.130 0.022"/>
    </geometry>
  </collision>

  <inertial>
    <origin xyz="0 0 0" rpy="0 0 0"/>
    <mass value="0.035"/>
    <inertia ixx="0.001"  ixy="0"  ixz="0" iyy="0.001" iyz="0" izz="0.001" />
  </inertial>
</link>

<joint name="camera_joint" type="fixed">
  <parent link="base_link"/>
  <child link="camera_link"/>
  <origin xyz="0.285 0 0.40" rpy="0 0 0"/>
</joint>

<link name="gyro_link"/>
<joint name="imu_joint" type="fixed">
  <parent link="base_link"/>
  <child link="gyro_link"/>
  <origin xyz="0.15 0 0.40" rpy="0 0 0"/>
</joint>


</robot>
